{
  "metadata": {
    "timestamp": "2025-02-26T12:20:26Z"
  },
  "data": [
    {
      "cve": {
        "id": "CVE-2022-36004",
        "description": "TensorFlow is an open source platform for machine learning. When `tf.random.gamma` receives large input shape and rates, it gives a `CHECK` fail that can trigger a denial of service attack. We have patched the issue in GitHub commit 552bfced6ce4809db5f3ca305f60ff80dd40c5a3. The fix will be included in TensorFlow 2.10.0. We will also cherrypick this commit on TensorFlow 2.9.1, TensorFlow 2.8.1, and TensorFlow 2.7.2, as these are also affected and still in supported range. There are no known workarounds for this issue.",
        "metadata": {
          "published_date": "2022-09-16T23:15:10.880",
          "last_modified_date": "2024-11-21T07:12:09.727",
          "confidence_level": "low",
          "severity": "high"
        },
        "impact": {
          "cisa_kev": false,
          "reported_exploited": false,
          "exploit_maturity": "none",
          "automatable": true
        },
        "counts": {
          "public_exploit_count": 0
        },
        "epss": {
          "score": 0.00082,
          "percentile": 0.37616
        },
        "metrics": [
          {
            "source": "nvd@nist.gov",
            "type": "Primary",
            "cvss_version": "3.1",
            "vector_string": "CVSS:3.1/AV:N/AC:L/PR:N/UI:N/S:U/C:N/I:N/A:H",
            "attack_vector": "NETWORK",
            "base_score": 7.5
          },
          {
            "source": "security-advisories@github.com",
            "type": "Secondary",
            "cvss_version": "3.1",
            "vector_string": "CVSS:3.1/AV:N/AC:H/PR:N/UI:N/S:U/C:N/I:N/A:H",
            "attack_vector": "NETWORK",
            "base_score": 5.90000009536743
          }
        ],
        "timeline": {
          "references": [],
          "repositories": []
        }
      }
    }
  ]
}