{
  "metadata": {
    "timestamp": "2025-02-27T02:47:37Z"
  },
  "data": [
    {
      "cve": {
        "id": "CVE-2022-1289",
        "description": "A denial of service vulnerability was found in tildearrow Furnace. It has been classified as problematic. This is due to an incomplete fix of CVE-2022-1211. It is possible to initiate the attack remotely but it requires user interaction. The issue got fixed with the patch 0eb02422d5161767e9983bdaa5c429762d3477ce.",
        "metadata": {
          "published": "",
          "last_modified": "",
          "confidence_level": "low",
          "severity": "medium",
          "source": "",
          "status": ""
        },
        "impact": {
          "cisa_kev": false,
          "reported_exploited": false,
          "exploit_maturity": "none",
          "automatable": false
        },
        "metrics": [
          {
            "source": "cna@vuldb.com",
            "type": "Secondary",
            "cvss_version": "3.1",
            "vector_string": "CVSS:3.1/AV:N/AC:L/PR:N/UI:R/S:U/C:N/I:N/A:L",
            "attack_vector": "NETWORK",
            "base_score": 4.30000019073486
          },
          {
            "source": "nvd@nist.gov",
            "type": "Primary",
            "cvss_version": "3.1",
            "vector_string": "CVSS:3.1/AV:N/AC:L/PR:N/UI:R/S:U/C:N/I:N/A:H",
            "attack_vector": "NETWORK",
            "base_score": 6.5
          },
          {
            "source": "nvd@nist.gov",
            "type": "Primary",
            "cvss_version": "2.0",
            "vector_string": "AV:N/AC:M/Au:N/C:N/I:N/A:P",
            "attack_vector": "NETWORK",
            "base_score": 4.30000019073486
          }
        ],
        "timeline": {
          "references": null,
          "repositories": null
        },
        "epss": {
          "score": 0.00163,
          "percentile": 0.5398
        },
        "counts": {
          "public_exploit_count": 0
        }
      }
    }
  ]
}